<mujoco model="yuuki_robot_biped">
  <!--
    ROBOT: 両脚バイペッド（docs/robot_spec.md・設計図に基づく）。
    片脚 1 本の exp_017 モデルではない。

    脚あたり 5 DOF（合計 10）: hip_roll → hip_pitch → knee_pitch → ankle_pitch → ankle_roll
    赤点・赤線（leg_servo_layout / biped_lower_body_structure）= サーボ軸の位置・向き。

    座標: +X 前, +Y 左, +Z 上。基準点はカゴ底面中央（basket_thigh の原点）。
    寸法 [m]: カゴ 0.28×0.145×0.18, 腿/脛セグメント各 0.20, サーボ 0.065 高,
    足裏板 0.25×0.10×0.002（Y 幅 10 cm、踵側 -1.5 cm はみ出し）, リポ 0.13×0.04×0.024（各腿セグメント内）。
    腿/脛フレーム: 単一 geom ではなく左右 3mm アルミ板 2 枚（4cm×20cm、各 63g）で挟み込み。

    関節 range 属性は度（exp_017 同様）。論理角は docs/human_joint_kinematics.md 参照。
    股ピッチは実機 kinematics（論理 60° = MuJoCo 0°）に合わせ MuJoCo -110°〜30°。
  -->

  <default>
    <site size="0.02" rgba="1 1 0 1"/>
    <joint damping="1.5" armature="0.02"/>
    <geom friction="1.15 0.005 0.0001"/>
  </default>

  <visual>
    <global offwidth="1280" offheight="960"/>
  </visual>

  <asset>
    <texture type="skybox" builtin="gradient" rgb1="1 1 1" rgb2=".6 .8 1" width="256" height="256"/>
    <texture name="grid" type="2d" builtin="checker" width="512" height="512" rgb1=".3 .1 .1" rgb2=".1 .1 .3"/>
    <material name="floor_mat" texture="grid" texrepeat="40 40"/>
    <material name="basket" rgba="0.85 0.82 0.7 1"/>
    <material name="servo" rgba="0.65 0.1 0.18 1"/>
    <material name="metal" rgba="0.7 0.7 0.7 1"/>
    <material name="lipo" rgba="0.95 0.55 0.1 0.85"/>
  </asset>

  <worldbody>
    <camera name="track_robot" mode="track" target="basket_thigh" pos="0 -2.6 1.2" fovy="48"/>
    <light pos="0 0 10" dir="0 0 -1" diffuse="0.8 0.8 0.8"/>
    <geom name="floor" type="plane" size="25 25 0.1" material="floor_mat"/>

    <!-- カゴ底面中央 = ルート原点。立位で足底が床に届く高さ -->
    <body name="basket_thigh" pos="0 0 0.66">
      <freejoint name="root"/>
      <site name="imu_site" pos="0 0 0.05"/>

      <!-- カゴ: 幅28cm(Y) × 高14.5cm(Z) × 奥行18cm(X) -->
      <geom name="basket" type="box" pos="0 0 0.0725" size="0.09 0.14 0.0725" material="basket" mass="0.5"/>

      <!-- ========== 左脚 (+Y) ========== -->
      <body name="left_hip" pos="0 0.12 0">
        <!-- 軸: ロール (X) — 背面図は点、側面図は線 -->
        <!-- 股ロール: 実機 LOGICAL_RANGE_HIP1（-30°〜90°） -->
        <joint name="left_hip_roll" type="hinge" axis="1 0 0" range="-30 90" damping="2"/>
        <geom name="left_hip_roll_servo" type="box" pos="0 0 -0.0325" size="0.015 0.024 0.0325" material="servo" mass="0.18" contype="0" conaffinity="0"/>

        <body name="left_thigh" pos="0 0 -0.065">
          <!-- 軸: ピッチ (Y) -->
          <!-- 股ピッチ論理角 -20°〜120° → MuJoCo（論理-90°）-110°〜30° -->
          <joint name="left_hip_pitch" type="hinge" axis="0 1 0" range="-110 30" damping="2"/>
          <!-- 腿板×2: 板面は X-Z、厚み 3mm は Y。サーボ幅 48mm の両脇に配置 -->
          <geom name="left_thigh_plate_outer" type="box" pos="0 0.0255 -0.10" size="0.02 0.0015 0.10" material="metal" mass="0.063"/>
          <geom name="thigh_link" type="box" pos="0 -0.0255 -0.10" size="0.02 0.0015 0.10" material="metal" mass="0.063"/>
          <geom name="left_thigh_lipo" type="box" pos="0 0 -0.10" size="0.012 0.02 0.065" material="lipo" mass="0.302" contype="0" conaffinity="0"/>

          <body name="left_knee" pos="0 0 -0.20">
            <!-- 膝: 真下 0°、後方屈曲 +（論理 0°〜100°） -->
            <joint name="left_knee_pitch" type="hinge" axis="0 1 0" range="0 100" damping="2"/>
            <geom name="left_knee_servo" type="box" pos="0 0 -0.0325" size="0.015 0.024 0.0325" material="servo" mass="0.18" contype="0" conaffinity="0"/>

            <body name="left_shin" pos="0 0 -0.065">
              <geom name="left_shin_plate_outer" type="box" pos="0 0.0255 -0.10" size="0.02 0.0015 0.10" material="metal" mass="0.063"/>
              <geom name="shank_link" type="box" pos="0 -0.0255 -0.10" size="0.02 0.0015 0.10" material="metal" mass="0.063"/>
              <geom name="left_shin_lipo" type="box" pos="0 0 -0.10" size="0.012 0.02 0.065" material="lipo" mass="0.302" contype="0" conaffinity="0"/>

              <body name="left_ankle_pitch" pos="0 0 -0.20">
                <!-- 足首ピッチ: 背屈 -20°、底屈 +90°（論理角） -->
                <joint name="left_ankle_pitch" type="hinge" axis="0 1 0" range="-20 90" damping="2"/>
                <geom name="left_ankle_pitch_servo" type="box" pos="0 0 -0.0325" size="0.015 0.024 0.0325" material="servo" mass="0.18" contype="0" conaffinity="0"/>

                <body name="left_ankle_roll" pos="0 0 -0.065">
                  <joint name="left_ankle_roll" type="hinge" axis="1 0 0" range="-20 20" damping="2"/>
                  <geom name="left_ankle_roll_servo" type="box" pos="0 0 -0.0325" size="0.015 0.024 0.0325" material="servo" mass="0.18" contype="0" conaffinity="0"/>

                  <body name="left_sole" pos="0 0 -0.065">
                    <site name="foot_site" pos="0.11 0 0.001"/>
                    <site name="heel_bottom_site" pos="-0.015 0 0"/>
                    <site name="toe_bottom_site" pos="0.215 0 0"/>
                    <geom name="foot_plate" type="box" pos="0.11 0 0.001" size="0.125 0.05 0.001" material="metal" mass="0.226"/>
                  </body>
                </body>
              </body>
            </body>
          </body>
        </body>
      </body>

      <!-- ========== 右脚 (-Y) ========== -->
      <body name="right_hip" pos="0 -0.12 0">
        <joint name="right_hip_roll" type="hinge" axis="1 0 0" range="-30 90" damping="2"/>
        <geom name="right_hip_roll_servo" type="box" pos="0 0 -0.0325" size="0.015 0.024 0.0325" material="servo" mass="0.18" contype="0" conaffinity="0"/>

        <body name="right_thigh" pos="0 0 -0.065">
          <joint name="right_hip_pitch" type="hinge" axis="0 1 0" range="-110 30" damping="2"/>
          <geom name="right_thigh_plate_outer" type="box" pos="0 -0.0255 -0.10" size="0.02 0.0015 0.10" material="metal" mass="0.063"/>
          <geom name="right_thigh_link" type="box" pos="0 0.0255 -0.10" size="0.02 0.0015 0.10" material="metal" mass="0.063"/>
          <geom name="right_thigh_lipo" type="box" pos="0 0 -0.10" size="0.012 0.02 0.065" material="lipo" mass="0.302" contype="0" conaffinity="0"/>

          <body name="right_knee" pos="0 0 -0.20">
            <joint name="right_knee_pitch" type="hinge" axis="0 1 0" range="0 100" damping="2"/>
            <geom name="right_knee_servo" type="box" pos="0 0 -0.0325" size="0.015 0.024 0.0325" material="servo" mass="0.18" contype="0" conaffinity="0"/>

            <body name="right_shin" pos="0 0 -0.065">
              <geom name="right_shin_plate_outer" type="box" pos="0 -0.0255 -0.10" size="0.02 0.0015 0.10" material="metal" mass="0.063"/>
              <geom name="right_shin_link" type="box" pos="0 0.0255 -0.10" size="0.02 0.0015 0.10" material="metal" mass="0.063"/>
              <geom name="right_shin_lipo" type="box" pos="0 0 -0.10" size="0.012 0.02 0.065" material="lipo" mass="0.302" contype="0" conaffinity="0"/>

              <body name="right_ankle_pitch" pos="0 0 -0.20">
                <joint name="right_ankle_pitch" type="hinge" axis="0 1 0" range="-20 90" damping="2"/>
                <geom name="right_ankle_pitch_servo" type="box" pos="0 0 -0.0325" size="0.015 0.024 0.0325" material="servo" mass="0.18" contype="0" conaffinity="0"/>

                <body name="right_ankle_roll" pos="0 0 -0.065">
                  <joint name="right_ankle_roll" type="hinge" axis="1 0 0" range="-20 20" damping="2"/>
                  <geom name="right_ankle_roll_servo" type="box" pos="0 0 -0.0325" size="0.015 0.024 0.0325" material="servo" mass="0.18" contype="0" conaffinity="0"/>

                  <body name="right_sole" pos="0 0 -0.065">
                    <site name="right_foot_site" pos="0.11 0 0.001"/>
                    <site name="right_heel_bottom_site" pos="-0.015 0 0"/>
                    <site name="right_toe_bottom_site" pos="0.215 0 0"/>
                    <geom name="right_foot_plate" type="box" pos="0.11 0 0.001" size="0.125 0.05 0.001" material="metal" mass="0.226"/>
                  </body>
                </body>
              </body>
            </body>
          </body>
        </body>
      </body>
    </body>
  </worldbody>

  <actuator>
    <!-- ctrlrange はラジアン。forcerange は RDS51150（150 kg·cm ≈ 14.7 N·m）飽和、全軸共通 -->
    <position name="left_hip_roll_motor" joint="left_hip_roll" kp="85" kv="12" ctrlrange="-0.524 1.571" forcelimited="true" forcerange="-14.7 14.7"/>
    <position name="left_hip_pitch_motor" joint="left_hip_pitch" kp="85" kv="12" ctrlrange="-1.919 0.524" forcelimited="true" forcerange="-14.7 14.7"/>
    <position name="left_knee_pitch_motor" joint="left_knee_pitch" kp="120" kv="14" ctrlrange="0 1.745" forcelimited="true" forcerange="-14.7 14.7"/>
    <position name="left_ankle_pitch_motor" joint="left_ankle_pitch" kp="70" kv="10" ctrlrange="-0.349 1.571" forcelimited="true" forcerange="-14.7 14.7"/>
    <position name="left_ankle_roll_motor" joint="left_ankle_roll" kp="50" kv="8" ctrlrange="-0.349 0.349" forcelimited="true" forcerange="-14.7 14.7"/>

    <position name="right_hip_roll_motor" joint="right_hip_roll" kp="85" kv="12" ctrlrange="-0.524 1.571" forcelimited="true" forcerange="-14.7 14.7"/>
    <position name="right_hip_pitch_motor" joint="right_hip_pitch" kp="85" kv="12" ctrlrange="-1.919 0.524" forcelimited="true" forcerange="-14.7 14.7"/>
    <position name="right_knee_pitch_motor" joint="right_knee_pitch" kp="120" kv="14" ctrlrange="0 1.745" forcelimited="true" forcerange="-14.7 14.7"/>
    <position name="right_ankle_pitch_motor" joint="right_ankle_pitch" kp="70" kv="10" ctrlrange="-0.349 1.571" forcelimited="true" forcerange="-14.7 14.7"/>
    <position name="right_ankle_roll_motor" joint="right_ankle_roll" kp="50" kv="8" ctrlrange="-0.349 0.349" forcelimited="true" forcerange="-14.7 14.7"/>
  </actuator>

  <sensor>
    <gyro name="imu_gyro" site="imu_site"/>
    <framezaxis name="imu_zaxis" objtype="site" objname="imu_site"/>
    <framexaxis name="foot_xaxis" objtype="site" objname="foot_site"/>
    <framezaxis name="foot_zaxis" objtype="site" objname="foot_site"/>
    <framepos name="toe_pos" objtype="site" objname="toe_bottom_site"/>
  </sensor>

  <!-- 立位: 全関節 MuJoCo 0° ≒ 論理角 hip2=60°, knee=30°, heel=-30° -->
  <keyframe>
    <key name="stand"
      qpos="0 0 0.66 1 0 0 0  0 0 0 0 0  0 0 0 0 0"
      ctrl="0 0 0 0 0  0 0 0 0 0"/>
  </keyframe>
</mujoco>
